Workbook

Sheet КП
B1: Заполняются только ячейки, выделенные синим цветом. Менять формулы и объемы недопустимо.
B4: Предмет тендера: | D4: Кровля подземной автостоянки в осях П24-П48
B5: Объект: | D5: Многоквартирные жилые дома со встроенными нежилыми помещениями и подземной автостоянкой, Блоки 13A и 13B
B6: Адрес объекта: | D6: г. Москва, вн.тер.г. муниципальный округ Покровское-Стрешнево, ул. Лётная, к/н 77:08:0015001:18981
B9: Наименование контрагента
B10: ИНН
B11: Адрес (юр., факт.)
A14: № п/п | B14: КОД | C14: Вид затрат | D14: Наименование затрат | E14: Примечание к расчету | F14: Ед. изм. | G14: Объем по виду работ | H14: Общий расход по материалу | I14: Цена за единицу, руб. с НДС | K14: Цена за единицу ИТОГО, руб. с НДС | L14: Стоимость ИТОГО, руб с НДС | N14: Общая стоимость, руб. с НДС | O14: Примечание участника тендера
I15: Материалы/ оборудование | J15: СМР, ПНР | L15: Материалы/ оборудование | M15: СМР, ПНР
A16: 1 | B16: 2 | C16: 3 | D16: 4 | E16: 5 | F16: 6 | G16: 7 | H16: 8 | I16: 9 | J16: 10 | K16: 11 | L16: 12 | M16: 13 | N16: 14 | O16: 15
D17: Устройство гидроизоляции кровли подземной автостоянки в осях П24-П48 | L17: =SUBTOTAL(9,L18:L79) -> 0 | M17: =SUBTOTAL(9,M18:M79) -> 0 | N17: =SUBTOTAL(9,N18:N74) -> 0
A18: 1 | D18: Устройство покрытия кровли Тип 1.1 (основная кровля) | L18: =SUBTOTAL(9,L19:L31) -> 0 | M18: =SUBTOTAL(9,M19:M31) -> 0 | N18: =SUBTOTAL(9,N19:N31) -> 0
A19: 1.1 | C19: Работа | D19: Устройство уклонообразующего слоя из керамзитобетона | F19: м3 | G19: 866.38 | I19: =SUMPRODUCT(G20:G20,I20:I20)/G19 -> 0 | J19: 0 | K19: =SUM(I19:J19) -> 0 | L19: =G19*I19 -> 0 | M19: =J19*G19 -> 0 | N19: =SUM(L19:M19) -> 0
A20: 1.1.1 | C20: Мат | D20: Керамзитобетон (керамзитовый гравий фр.20-40мм, П35, М250) | F20: м3 | G20: =G19*H20 -> 909.699 | H20: 1.05 | I20: 0
A21: 1.2 | C21: Работа | D21: Устройство стяжки толщиной 50 мм | F21: м2 | G21: 5035.44 | I21: =SUMPRODUCT(G22:G23,I22:I23)/G21 -> 0 | J21: 0 | K21: =SUM(I21:J21) -> 0 | L21: =G21*I21 -> 0 | M21: =J21*G21 -> 0 | N21: =SUM(L21:M21) -> 0
A22: 1.2.1 | C22: Мат | D22: Сетка 4Вр-1-100х100 | F22: м2 | G22: =G21*H22 -> 5538.984 | H22: 1.1 | I22: 0
A23: 1.2.2 | C23: Мат | D23: Раствор М150 | F23: м3 | G23: =G21*H23*0.05 -> 264.3606 | H23: 1.05 | I23: 0
A24: 1.3 | C24: Работа | D24: Огрунтовка поверхности | F24: м2 | G24: 5035.44 | I24: =SUMPRODUCT(G25:G25,I25:I25)/G24 -> 0 | J24: 0 | K24: =SUM(I24:J24) -> 0 | L24: =G24*I24 -> 0 | M24: =J24*G24 -> 0 | N24: =SUM(L24:M24) -> 0
A25: 1.3.1 | C25: Мат | D25: Праймер Технониколь №1 | F25: м2 | G25: =G24*H25 -> 5790.756 | H25: 1.15 | I25: 0
A26: 1.4 | C26: Работа | D26: Устройство изоляции горизонтальной в 2 слоя | F26: м2 | G26: 5035.44 | I26: =SUMPRODUCT(G27:G27,I27:I27)/G26 -> 0 | J26: 0 | K26: =SUM(I26:J26) -> 0 | L26: =G26*I26 -> 0 | M26: =J26*G26 -> 0 | N26: =SUM(L26:M26) -> 0
A27: 1.4.1 | C27: Мат | D27: Техноэласт ЭПП | F27: м2 | G27: =G26*H27*2 -> 11581.512 | H27: 1.15 | I27: 0
A28: 1.5 | C28: Работа | D28: Устройство утеплителя в 1 слой | F28: м2 | G28: 5035.44 | I28: =SUMPRODUCT(G29:G29,I29:I29)/G28 -> 0 | J28: 0 | K28: =SUM(I28:J28) -> 0 | L28: =G28*I28 -> 0 | M28: =J28*G28 -> 0 | N28: =SUM(L28:M28) -> 0
A29: 1.5.1 | C29: Мат | D29: Экструдированный пенополистирол Технониколь Carbon Prof 500 - 150 мм | F29: м2 | G29: =G28*H29 -> 5186.5032 | H29: 1.03 | I29: 0
A30: 1.6 | C30: Работа | D30: Устройство горизонтальной профилированной мембраны | F30: м2 | G30: 5035.44 | I30: =SUMPRODUCT(G31:G31,I31:I31)/G30 -> 0 | J30: 0 | K30: =SUM(I30:J30) -> 0 | L30: =G30*I30 -> 0 | M30: =J30*G30 -> 0 | N30: =SUM(L30:M30) -> 0
A31: 1.6.1 | C31: Мат | D31: Профилированная мембрана Planter geo - 10 мм | F31: м2 | G31: =G30*H31 -> 5639.6928 | H31: 1.12 | I31: 0
A32: 2 | D32: Устройство покрытия кровли Тип 1.2 (участки прилегающие к стенам и краям) | L32: =SUBTOTAL(9,L33:L47) -> 0 | M32: =SUBTOTAL(9,M33:M47) -> 0 | N32: =SUBTOTAL(9,N33:N47) -> 0
A33: 2.1 | C33: Работа | D33: Устройство уклонообразующего слоя из керамзитобетона | F33: м3 | G33: 122.74 | I33: =SUMPRODUCT(G34:G34,I34:I34)/G33 -> 0 | J33: 0 | K33: =SUM(I33:J33) -> 0 | L33: =G33*I33 -> 0 | M33: =J33*G33 -> 0 | N33: =SUM(L33:M33) -> 0
A34: 2.1.1 | C34: Мат | D34: Керамзитобетон (керамзитовый гравий фр.20-40мм, П35, М250) | F34: м3 | G34: =G33*H34 -> 128.877 | H34: 1.05 | I34: 0
A35: 2.2 | C35: Работа | D35: Устройство стяжки толщиной 50 мм | F35: м2 | G35: 697.31 | I35: =SUMPRODUCT(G36:G37,I36:I37)/G35 -> 0 | J35: 0 | K35: =SUM(I35:J35) -> 0 | L35: =G35*I35 -> 0 | M35: =J35*G35 -> 0 | N35: =SUM(L35:M35) -> 0
A36: 2.2.1 | C36: Мат | D36: Сетка 4Вр-1-100х100 | F36: м2 | G36: =G35*H36 -> 767.041 | H36: 1.1 | I36: 0
A37: 2.2.2 | C37: Мат | D37: Раствор М150 | F37: м3 | G37: =G35*H37*0.05 -> 36.608775 | H37: 1.05 | I37: 0
A38: 2.3 | C38: Работа | D38: Устройство разделительного слоя | F38: м2 | G38: 697.31 | I38: =SUMPRODUCT(G39:G39,I39:I39)/G38 -> 0 | J38: 0 | K38: =SUM(I38:J38) -> 0 | L38: =G38*I38 -> 0 | M38: =J38*G38 -> 0 | N38: =SUM(L38:M38) -> 0
A39: 2.3.1 | C39: Мат | D39: Геотекстильное полотно Технониколь 500 г/м2 | F39: м2 | G39: =G38*H39 -> 801.9065 | H39: 1.15 | I39: 0
A40: 2.4 | C40: Работа | D40: Устройство изоляции горизонтальной в 1 слой | F40: м2 | G40: 697.31 | I40: =SUMPRODUCT(G41:G41,I41:I41)/G40 -> 0 | J40: 0 | K40: =SUM(I40:J40) -> 0 | L40: =G40*I40 -> 0 | M40: =J40*G40 -> 0 | N40: =SUM(L40:M40) -> 0
A41: 2.4.1 | C41: Мат | D41: Гидроизоляционная мембрана LOGICBASE V-SL | F41: м2 | G41: =G40*H41 -> 801.9065 | H41: 1.15 | I41: 0
A42: 2.5 | C42: Работа | D42: Устройство разделительного слоя | F42: м2 | G42: 697.31 | I42: =SUMPRODUCT(G43:G43,I43:I43)/G42 -> 0 | J42: 0 | K42: =SUM(I42:J42) -> 0 | L42: =G42*I42 -> 0 | M42: =J42*G42 -> 0 | N42: =SUM(L42:M42) -> 0
A43: 2.5.1 | C43: Мат | D43: Геотекстильное полотно Технониколь 500 г/м2 | F43: м2 | G43: =G42*H43 -> 801.9065 | H43: 1.15 | I43: 0
A44: 2.6 | C44: Работа | D44: Устройство утеплителя в 1 слой | F44: м2 | G44: 697.31 | I44: =SUMPRODUCT(G45:G45,I45:I45)/G44 -> 0 | J44: 0 | K44: =SUM(I44:J44) -> 0 | L44: =G44*I44 -> 0 | M44: =J44*G44 -> 0 | N44: =SUM(L44:M44) -> 0
A45: 2.6.1 | C45: Мат | D45: Экструдированный пенополистирол Технониколь Carbon Prof 500 - 150 мм | F45: м2 | G45: =G44*H45 -> 718.2293 | H45: 1.03 | I45: 0
A46: 2.7 | C46: Работа | D46: Устройство горизонтальной профилированной мембраны | F46: м2 | G46: 697.31 | I46: =SUMPRODUCT(G47:G47,I47:I47)/G46 -> 0 | J46: 0 | K46: =SUM(I46:J46) -> 0 | L46: =G46*I46 -> 0 | M46: =J46*G46 -> 0 | N46: =SUM(L46:M46) -> 0
...

Sheet БСМ
B1: Базовая стоимость ресурсов (материалов)
A2: № п/п | B2: Наименование материала | C2: Ед. изм. | D2: ЦЕНА руб., с НДС/ед. с доставкой
A3: 1 | B3: 2 | C3: 3 | D3: 4
A4: 1 | B4: Керамзитобетон (керамзитовый гравий фр.20-40мм, П35, М250) | C4: м3 | D4: =_xlfn.XLOOKUP(B4,КП!D:D,КП!I:I) -> 0
A5: 2 | B5: Сетка 4Вр-1-100х100 | C5: м2 | D5: =_xlfn.XLOOKUP(B5,КП!D:D,КП!I:I) -> 0
A6: 3 | B6: Раствор М150 | C6: м3 | D6: =_xlfn.XLOOKUP(B6,КП!D:D,КП!I:I) -> 0
A7: 4 | B7: Праймер Технониколь №1 | C7: м2 | D7: =_xlfn.XLOOKUP(B7,КП!D:D,КП!I:I) -> 0
A8: 5 | B8: Техноэласт ЭПП | C8: м2 | D8: =_xlfn.XLOOKUP(B8,КП!D:D,КП!I:I) -> 0
A9: 6 | B9: Экструдированный пенополистирол Технониколь Carbon Prof 500 - 150 мм | C9: м2 | D9: =_xlfn.XLOOKUP(B9,КП!D:D,КП!I:I) -> 0
A10: 7 | B10: Профилированная мембрана Planter geo - 10 мм | C10: м2 | D10: =_xlfn.XLOOKUP(B10,КП!D:D,КП!I:I) -> 0
A11: 8 | B11: Геотекстильное полотно Технониколь 500 г/м2 | C11: м2 | D11: =_xlfn.XLOOKUP(B11,КП!D:D,КП!I:I) -> 0
A12: 9 | B12: Гидроизоляционная мембрана LOGICBASE V-SL | C12: м2 | D12: =_xlfn.XLOOKUP(B12,КП!D:D,КП!I:I) -> 0
A13: 10 | B13: Керамзитовый гравий с фракцией 5-10 мм, плотностью М600 | C13: м3 | D13: =_xlfn.XLOOKUP(B13,КП!D:D,КП!I:I) -> 0
A14: 10 | B14: Воронка кровельная водоприемная | C14: шт | D14: 0
